Workbook

Sheet Памятка
A1: Программа: Верх / Низ, 4 дня — гибрид СИЛА + МАССА (средний уровень)
A2: Дни: Пн — Верх A · Вт — Низ A · Чт — Верх B · Пт — Низ B (быстрый, ~1 ч, можно пропускать)
A4: ГЛАВНЫЕ ПРИНЦИПЫ
A5: • Каждая мышца — 2 раза в неделю. Недельный объём 10–16 рабочих подходов на крупную мышцу.
A6: • Силовое движение дня (оранжевое) — первым, тяжело: 4–5 подходов, малоповторка, отдых 2,5–3 мин, 1–2 повтора «в запасе».
A7: • Дальше — подсобка на массу: 3x8–15, отдых 60–90 сек, последние 1–2 подхода близко к отказу.
A8: • Прогрессия (double progression): добрал верх диапазона во всех подходах → +2,5–5 кг и снова с низа.
A10: ЖИМ ШТАНГИ ЛЁЖА — на максимум (Пн, первым)
A11: • Схема 5,5,3,3,2 с ростом веса; раз в 2–3 недели — «проходка» на 2–3 повтора. Всегда страховка/напарник.
A12: • Берегите плечо: хват не шире ~1,5 ширины плеч, лопатки сведены и опущены, локти не разводим в стороны (~45–75°), штангу к низу груди.
A13: • Если плечо снова заноет — первым облегчаем именно жим лёжа.
A15: ЗАЩИТА ПЛЕЧ
... A26: ЦИКЛ: 5–6 недель → 1 неделя разгрузки (вес −40%) → меняем вариации (лист «Замены») → новый блок.

Sheet План тренировок
A1: ДЕНЬ 1 — ПОНЕДЕЛЬНИК · ВЕРХ A (грудь + спина, силовой акцент)
A2: Жим штанги лёжа — ПЕРВЫМ, на максимум (оранжевое). Прехаб (зелёное) обязателен. ~80–90 мин.
A3: № | B3: Упражнение | C3: Группа / зачем | D3: Подходы | E3: Повторения | F3: Темп | G3: Отдых, сек | H3: Техника (ссылка)
A4: 1 | B4: Жим штанги лёжа | C4: Грудь (ГЛАВНОЕ, на максимум) | D4: 5 | E4: 5,5,3,3,2 | F4: 30X1 | G4: 180 | H4: смотреть ▶
A5: 2 | B5: Тяга штанги в наклоне | C5: Спина/толщина (главное, сила) | D5: 4 | E5: 6–8 | F5: 3010 | G5: 150 | H5: смотреть ▶
A6: 3 | B6: Жим гантелей на наклонной 30° | C6: Грудь, верх (подсобка) | D6: 3 | E6: 8–12 | F6: 3011 | G6: 90 | H6: смотреть ▶
A7: 4 | B7: Тяга верхнего блока нейтральным хватом | C7: Широчайшие (ширина) | D7: 3 | E7: 10–12 | F7: 2011 | G7: 90 | H7: смотреть ▶
A8: 5 | B8: Махи гантелями в стороны | C8: Средняя дельта (не выше плеч) | D8: 3 | E8: 12–15 | F8: 2010 | G8: 60 | H8: смотреть ▶
A9: 6 | B9: Французский жим / разгибания на блоке | C9: Трицепс | D9: 3 | E9: 10–12 | F9: 2011 | G9: 75 | H9: смотреть ▶
A10: 7 | B10: Подъём штанги на бицепс | C10: Бицепс | D10: 3 | E10: 10–12 | F10: 2011 | G10: 75 | H10: смотреть ▶
A11: П | B11: Внешняя ротация плеча на блоке | C11: ПРЕХАБ: манжета плеча | D11: 2 | E11: 15–20 | F11: 2011 | G11: 45 | H11: смотреть ▶
A13: ДЕНЬ 2 — ВТОРНИК · НИЗ A (квадрицепс, силовой акцент)
A14: Приседания — главное движение недели. ~70–80 мин.
A15: № | B15: Упражнение | C15: Группа / зачем | D15: Подходы | E15: Повторения | F15: Темп | G15: Отдых, сек | H15: Техника (ссылка)
A16: 1 | B16: Приседания со штангой (или в Смите) | C16: Квадрицепс (ГЛАВНОЕ, сила) | D16: 4 | E16: 5–6 | F16: 3010 | G16: 180 | H16: смотреть ▶
A17: 2 | B17: Гоблет-приседания (с гантелью/гирей) | C17: Квадрицепс/ягодицы | D17: 3 | E17: 10–12 | F17: 2011 | G17: 120 | H17: смотреть ▶
A18: 3 | B18: Румынская тяга со штангой/гантелями | C18: Бицепс бедра/ягодицы | D18: 3 | E18: 8–10 | F18: 3011 | G18: 120 | H18: смотреть ▶
A19: 4 | B19: Разгибание ног в тренажёре сидя | C19: Квадрицепс (изоляция) | D19: 3 | E19: 12–15 | F19: 2011 | G19: 75 | H19: смотреть ▶
A20: 5 | B20: Сгибание ног лёжа/сидя | C20: Бицепс бедра (изоляция) | D20: 3 | E20: 12–15 | F20: 2011 | G20: 75 | H20: смотреть ▶
A21: 6 | B21: Подъём на носки стоя (в Смите) | C21: Икры | D21: 4 | E21: 12–15 | F21: 2012 | G21: 60 | H21: смотреть ▶
A22: 7 | B22: Подъём ног в висе | C22: Пресс | D22: 3 | E22: 15–20 | F22: 2011 | G22: 60 | H22: смотреть ▶
A24: ДЕНЬ 3 — ЧЕТВЕРГ · ВЕРХ B (плечи + спина, акцент на массу)
A25: Единственный жим над головой — нейтральным хватом, бережно. Тяг больше, чем жимов. ~80–90 мин.
A26: № | B26: Упражнение | C26: Группа / зачем | D26: Подходы | E26: Повторения | F26: Темп | G26: Отдых, сек | H26: Техника (ссылка)
A27: 1 | B27: Жим гантелей сидя нейтральным хватом | C27: Плечи (единственный жим вверх, бережно) | D27: 4 | E27: 8–10 | F27: 3010 | G27: 120 | H27: смотреть ▶
A28: 2 | B28: Подтягивания / тяга верхнего блока к груди | C28: Спина/ширина (сила) | D28: 4 | E28: 8–10 | F28: 2011 | G28: 120 | H28: смотреть ▶
A29: 3 | B29: Тяга горизонтального блока к поясу | C29: Спина/толщина (тяг больше, чем жимов) | D29: 3 | E29: 10–12 | F29: 2011 | G29: 90 | H29: смотреть ▶
A30: 4 | B30: Сведение рук в кроссовере / бабочка | C30: Грудь (2-й раз за неделю) | D30: 3 | E30: 12–15 | F30: 2011 | G30: 75 | H30: смотреть ▶
A31: 5 | B31: Махи гантелями в стороны | C31: Средняя дельта | D31: 3 | E31: 12–15 | F31: 2010 | G31: 60 | H31: смотреть ▶
A32: 6 | B32: Тяга каната к лицу (face pull) | C32: ПРЕХАБ: задняя дельта + плечо | D32: 3 | E32: 15–20 | F32: 2012 | G32: 60 | H32: смотреть ▶
A33: 7 | B33: Сгибание рук «молот» | C33: Бицепс/брахиалис | D33: 3 | E33: 10–12 | F33: 2011 | G33: 75 | H33: смотреть ▶
A34: 8 | B34: Разгибание на блоке с канатом | C34: Трицепс | D34: 3 | E34: 12–15 | F34: 2011 | G34: 60 | H34: смотреть ▶
A36: ДЕНЬ 4 — ПЯТНИЦА · НИЗ B + руки (быстрый, ~1 ч, можно пропускать)
A37: Короткий, темповый, отдых минимальный. Если пропустили — программа НЕ ломается.
A38: № | B38: Упражнение | C38: Группа / зачем | D38: Подходы | E38: Повторения | F38: Темп | G38: Отдых, сек | H38: Техника (ссылка)
A39: 1 | B39: Гиперэкстензия (или румынская тяга) | C39: Задняя цепь (главное) | D39: 3 | E39: 10–12 | F39: 3011 | G39: 90 | H39: смотреть ▶
A40: 2 | B40: Болгарские выпады / выпады по залу | C40: Ноги целиком | D40: 3 | E40: 10–12 | F40: 2011 | G40: 90 | H40: смотреть ▶
A41: 3 | B41: Сгибание ног в тренажёре | C41: Бицепс бедра | D41: 3 | E41: 12–15 | F41: 2011 | G41: 60 | H41: смотреть ▶
A42: 4 | B42: Подъём на носки | C42: Икры | D42: 3 | E42: 15–20 | F42: 2012 | G42: 45 | H42: смотреть ▶
A43: 5 | B43: Суперсет: бицепс (молот) + трицепс (блок) | C43: Руки (пампинг) | D43: 3 | E43: 12 + 12 | F43: 2011 | G43: 60 | H43: смотреть ▶
...

Sheet Журнал
A1: Дата | B1: Кто | C1: Упражнение | D1: Вес, кг | E1: Повторы | F1: Тоннаж | G1: e1RM
A2: 46195 | B2: Егор | C2: Жим гантелей на наклонной 30° | D2: 24 | E2: 10 | F2: =IF(OR($D2="",$E2=""),"",$D2*$E2) -> 240 | G2: =IF(OR($D2="",$E2=""),"",ROUND($D2*(1+$E2/30),1)) -> 32
A3: 46195 | B3: Егор | C3: Жим гантелей на наклонной 30° | D3: 24 | E3: 12 | F3: =IF(OR($D3="",$E3=""),"",$D3*$E3) -> 288 | G3: =IF(OR($D3="",$E3=""),"",ROUND($D3*(1+$E3/30),1)) -> 33.6
A4: 46195 | B4: Егор | C4: Жим гантелей на наклонной 30° | D4: 24 | E4: 12 | F4: =IF(OR($D4="",$E4=""),"",$D4*$E4) -> 288 | G4: =IF(OR($D4="",$E4=""),"",ROUND($D4*(1+$E4/30),1)) -> 33.6
A5: 46195 | B5: Егор | C5: Жим гантелей на наклонной 30° | D5: 24 | E5: 12 | F5: =IF(OR($D5="",$E5=""),"",$D5*$E5) -> 288 | G5: =IF(OR($D5="",$E5=""),"",ROUND($D5*(1+$E5/30),1)) -> 33.6
A6: 46195 | B6: Данил | C6: Жим гантелей на наклонной 30° | D6: 14 | E6: 12 | F6: =IF(OR($D6="",$E6=""),"",$D6*$E6) -> 168 | G6: =IF(OR($D6="",$E6=""),"",ROUND($D6*(1+$E6/30),1)) -> 19.6
A7: 46195 | B7: Данил | C7: Жим гантелей на наклонной 30° | D7: 16 | E7: 12 | F7: =IF(OR($D7="",$E7=""),"",$D7*$E7) -> 192 | G7: =IF(OR($D7="",$E7=""),"",ROUND($D7*(1+$E7/30),1)) -> 22.4
A8: 46195 | B8: Данил | C8: Жим гантелей на наклонной 30° | D8: 18 | E8: 12 | F8: =IF(OR($D8="",$E8=""),"",$D8*$E8) -> 216 | G8: =IF(OR($D8="",$E8=""),"",ROUND($D8*(1+$E8/30),1)) -> 25.2
A9: 46195 | B9: Данил | C9: Жим гантелей на наклонной 30° | D9: 18 | E9: 8 | F9: =IF(OR($D9="",$E9=""),"",$D9*$E9) -> 144 | G9: =IF(OR($D9="",$E9=""),"",ROUND($D9*(1+$E9/30),1)) -> 22.8
A10: 46195 | B10: Егор | C10: Тяга штанги в наклоне | D10: 60 | E10: 10 | F10: =IF(OR($D10="",$E10=""),"",$D10*$E10) -> 600 | G10: =IF(OR($D10="",$E10=""),"",ROUND($D10*(1+$E10/30),1)) -> 80
A11: 46195 | B11: Егор | C11: Тяга штанги в наклоне | D11: 70 | E11: 10 | F11: =IF(OR($D11="",$E11=""),"",$D11*$E11) -> 700 | G11: =IF(OR($D11="",$E11=""),"",ROUND($D11*(1+$E11/30),1)) -> 93.3
A12: 46195 | B12: Егор | C12: Тяга штанги в наклоне | D12: 70 | E12: 10 | F12: =IF(OR($D12="",$E12=""),"",$D12*$E12) -> 700 | G12: =IF(OR($D12="",$E12=""),"",ROUND($D12*(1+$E12/30),1)) -> 93.3
A13: 46195 | B13: Егор | C13: Тяга штанги в наклоне | D13: 70 | E13: 10 | F13: =IF(OR($D13="",$E13=""),"",$D13*$E13) -> 700 | G13: =IF(OR($D13="",$E13=""),"",ROUND($D13*(1+$E13/30),1)) -> 93.3
... A91: 46196 | B91: Егор | C91: Подъём на носки | D91: 50 | E91: 16 | F91: =IF(OR($D91="",$E91=""),"",$D91*$E91) -> 800 | G91: =IF(OR($D91="",$E91=""),"",ROUND($D91*(1+$E91/30),1)) -> 76.7
A92: 46196 | B92: Данил | C92: Подъём ног в висе | E92: 12 | F92: =IF(OR($D92="",$E92=""),"",$D92*$E92) | G92: =IF(OR($D92="",$E92=""),"",ROUND($D92*(1+$E92/30),1))
A93: 46196 | B93: Данил | C93: Подъём ног в висе | E93: 12 | F93: =IF(OR($D93="",$E93=""),"",$D93*$E93) | G93: =IF(OR($D93="",$E93=""),"",ROUND($D93*(1+$E93/30),1))
A94: 46196 | B94: Данил | C94: Подъём ног в висе | E94: 12 | F94: =IF(OR($D94="",$E94=""),"",$D94*$E94) | G94: =IF(OR($D94="",$E94=""),"",ROUND($D94*(1+$E94/30),1))
F95: =IF(OR($D95="",$E95=""),"",$D95*$E95) | G95: =IF(OR($D95="",$E95=""),"",ROUND($D95*(1+$E95/30),1))
F96: =IF(OR($D96="",$E96=""),"",$D96*$E96) | G96: =IF(OR($D96="",$E96=""),"",ROUND($D96*(1+$E96/30),1))
F97: =IF(OR($D97="",$E97=""),"",$D97*$E97) | G97: =IF(OR($D97="",$E97=""),"",ROUND($D97*(1+$E97/30),1))
F98: =IF(OR($D98="",$E98=""),"",$D98*$E98) | G98: =IF(OR($D98="",$E98=""),"",ROUND($D98*(1+$E98/30),1))
F99: =IF(OR($D99="",$E99=""),"",$D99*$E99) | G99: =IF(OR($D99="",$E99=""),"",ROUND($D99*(1+$E99/30),1))
F100: =IF(OR($D100="",$E100=""),"",$D100*$E100) | G100: =IF(OR($D100="",$E100=""),"",ROUND($D100*(1+$E100/30),1))
F101: =IF(OR($D101="",$E101=""),"",$D101*$E101) | G101: =IF(OR($D101="",$E101=""),"",ROUND($D101*(1+$E101/30),1))
F102: =IF(OR($D102="",$E102=""),"",$D102*$E102) | G102: =IF(OR($D102="",$E102=""),"",ROUND($D102*(1+$E102/30),1))
F103: =IF(OR($D103="",$E103=""),"",$D103*$E103) | G103: =IF(OR($D103="",$E103=""),"",ROUND($D103*(1+$E103/30),1))
F104: =IF(OR($D104="",$E104=""),"",$D104*$E104) | G104: =IF(OR($D104="",$E104=""),"",ROUND($D104*(1+$E104/30),1))
F105: =IF(OR($D105="",$E105=""),"",$D105*$E105) | G105: =IF(OR($D105="",$E105=""),"",ROUND($D105*(1+$E105/30),1))
F106: =IF(OR($D106="",$E106=""),"",$D106*$E106) | G106: =IF(OR($D106="",$E106=""),"",ROUND($D106*(1+$E106/30),1))
... F600: =IF(OR($D600="",$E600=""),"",$D600*$E600) | G600: =IF(OR($D600="",$E600=""),"",ROUND($D600*(1+$E600/30),1))

Sheet Статистика
A1: СТАТИСТИКА ПРОГРЕССА · Старт = лучший e1RM на 1-й тренировке, Сейчас = на последней. Заполняй «Журнал» — пересчитается само.
B2: ДАНИЛ | E2: ЕГОР
A3: Упражнение | B3: Старт e1RM | C3: Сейчас | D3: Δ % | E3: Старт e1RM | F3: Сейчас | G3: Δ %
A4: Жим штанги лёжа | B4: {=IF(COUNTIFS('Журнал'!$C$2:$C$600,$A4,'Журнал'!$B$2:$B$600,"Данил")=0,"",MAX(IF(('Журнал'!$C$2:$C$600=$A4)*('Журнал'!$B$2:$B$600="Данил")*('Журнал'!$A$2:$A$600=MIN(IF(('Журнал'!$C$2:$C$600=$A4)*('Журнал'!$B$2:$B$600="Данил"),'Журнал'!$A$2:$A$600,""))),'Журнал'!$G$2:$G$600,"")))} | C4: {=IF(COUNTIFS('Журнал'!$C$2:$C$600,$A4,'Журнал'!$B$2:$B$600,"Данил")=0,"",MAX(IF(('Журнал'!$C$2:$C$600=$A4)*('Журнал'!$B$2:$B$600="Данил")*('Журнал'!$A$2:$A$600=MAX(IF(('Журнал'!$C$2:$C$600=$A4)*('Журнал'!$B$2:$B$600="Данил"),'Журнал'!$A$2:$A$600,""))),'Журнал'!$G$2:$G$600,"")))} | D4: =IF(OR(B4="",B4=0),"",C4/B4-1) | E4: {=IF(COUNTIFS('Журнал'!$C$2:$C$600,$A4,'Журнал'!$B$2:$B$600,"Егор")=0,"",MAX(IF(('Журнал'!$C$2:$C$600=$A4)*('Журнал'!$B$2:$B$600="Егор")*('Журнал'!$A$2:$A$600=MIN(IF(('Журнал'!$C$2:$C$600=$A4)*('Журнал'!$B$2:$B$600="Егор"),'Журнал'!$A$2:$A$600,""))),'Журнал'!$G$2:$G$600,"")))} | F4: {=IF(COUNTIFS('Журнал'!$C$2:$C$600,$A4,'Журнал'!$B$2:$B$600,"Егор")=0,"",MAX(IF(('Журнал'!$C$2:$C$600=$A4)*('Журнал'!$B$2:$B$600="Егор")*('Журнал'!$A$2:$A$600=MAX(IF(('Журнал'!$C$2:$C$600=$A4)*('Журнал'!$B$2:$B$600="Егор"),'Журнал'!$A$2:$A$600,""))),'Журнал'!$G$2:$G$600,"")))} | G4: =IF(OR(E4="",E4=0),"",F4/E4-1)
A5: Приседания со штангой | B5: {=IF(COUNTIFS('Журнал'!$C$2:$C$600,$A5,'Журнал'!$B$2:$B$600,"Данил")=0,"",MAX(IF(('Журнал'!$C$2:$C$600=$A5)*('Журнал'!$B$2:$B$600="Данил")*('Журнал'!$A$2:$A$600=MIN(IF(('Журнал'!$C$2:$C$600=$A5)*('Журнал'!$B$2:$B$600="Данил"),'Журнал'!$A$2:$A$600,""))),'Журнал'!$G$2:$G$600,"")))} -> 66.7 | C5: {=IF(COUNTIFS('Журнал'!$C$2:$C$600,$A5,'Журнал'!$B$2:$B$600,"Данил")=0,"",MAX(IF(('Журнал'!$C$2:$C$600=$A5)*('Журнал'!$B$2:$B$600="Данил")*('Журнал'!$A$2:$A$600=MAX(IF(('Журнал'!$C$2:$C$600=$A5)*('Журнал'!$B$2:$B$600="Данил"),'Журнал'!$A$2:$A$600,""))),'Журнал'!$G$2:$G$600,"")))} -> 66.7 | D5: =IF(OR(B5="",B5=0),"",C5/B5-1) -> 0 | E5: {=IF(COUNTIFS('Журнал'!$C$2:$C$600,$A5,'Журнал'!$B$2:$B$600,"Егор")=0,"",MAX(IF(('Журнал'!$C$2:$C$600=$A5)*('Журнал'!$B$2:$B$600="Егор")*('Журнал'!$A$2:$A$600=MIN(IF(('Журнал'!$C$2:$C$600=$A5)*('Журнал'!$B$2:$B$600="Егор"),'Журнал'!$A$2:$A$600,""))),'Журнал'!$G$2:$G$600,"")))} -> 144 | F5: {=IF(COUNTIFS('Журнал'!$C$2:$C$600,$A5,'Журнал'!$B$2:$B$600,"Егор")=0,"",MAX(IF(('Журнал'!$C$2:$C$600=$A5)*('Журнал'!$B$2:$B$600="Егор")*('Журнал'!$A$2:$A$600=MAX(IF(('Журнал'!$C$2:$C$600=$A5)*('Журнал'!$B$2:$B$600="Егор"),'Журнал'!$A$2:$A$600,""))),'Журнал'!$G$2:$G$600,"")))} -> 144 | G5: =IF(OR(E5="",E5=0),"",F5/E5-1) -> 0
A6: Тяга штанги в наклоне | B6: {=IF(COUNTIFS('Журнал'!$C$2:$C$600,$A6,'Журнал'!$B$2:$B$600,"Данил")=0,"",MAX(IF(('Журнал'!$C$2:$C$600=$A6)*('Журнал'!$B$2:$B$600="Данил")*('Журнал'!$A$2:$A$600=MIN(IF(('Журнал'!$C$2:$C$600=$A6)*('Журнал'!$B$2:$B$600="Данил"),'Журнал'!$A$2:$A$600,""))),'Журнал'!$G$2:$G$600,"")))} -> 56 | C6: {=IF(COUNTIFS('Журнал'!$C$2:$C$600,$A6,'Журнал'!$B$2:$B$600,"Данил")=0,"",MAX(IF(('Журнал'!$C$2:$C$600=$A6)*('Журнал'!$B$2:$B$600="Данил")*('Журнал'!$A$2:$A$600=MAX(IF(('Журнал'!$C$2:$C$600=$A6)*('Журнал'!$B$2:$B$600="Данил"),'Журнал'!$A$2:$A$600,""))),'Журнал'!$G$2:$G$600,"")))} -> 56 | D6: =IF(OR(B6="",B6=0),"",C6/B6-1) -> 0 | E6: {=IF(COUNTIFS('Журнал'!$C$2:$C$600,$A6,'Журнал'!$B$2:$B$600,"Егор")=0,"",MAX(IF(('Журнал'!$C$2:$C$600=$A6)*('Журнал'!$B$2:$B$600="Егор")*('Журнал'!$A$2:$A$600=MIN(IF(('Журнал'!$C$2:$C$600=$A6)*('Журнал'!$B$2:$B$600="Егор"),'Журнал'!$A$2:$A$600,""))),'Журнал'!$G$2:$G$600,"")))} -> 93.3 | F6: {=IF(COUNTIFS('Журнал'!$C$2:$C$600,$A6,'Журнал'!$B$2:$B$600,"Егор")=0,"",MAX(IF(('Журнал'!$C$2:$C$600=$A6)*('Журнал'!$B$2:$B$600="Егор")*('Журнал'!$A$2:$A$600=MAX(IF(('Журнал'!$C$2:$C$600=$A6)*('Журнал'!$B$2:$B$600="Егор"),'Журнал'!$A$2:$A$600,""))),'Журнал'!$G$2:$G$600,"")))} -> 93.3 | G6: =IF(OR(E6="",E6=0),"",F6/E6-1) -> 0
A7: Жим гантелей сидя | B7: {=IF(COUNTIFS('Журнал'!$C$2:$C$600,$A7,'Журнал'!$B$2:$B$600,"Данил")=0,"",MAX(IF(('Журнал'!$C$2:$C$600=$A7)*('Журнал'!$B$2:$B$600="Данил")*('Журнал'!$A$2:$A$600=MIN(IF(('Журнал'!$C$2:$C$600=$A7)*('Журнал'!$B$2:$B$600="Данил"),'Журнал'!$A$2:$A$600,""))),'Журнал'!$G$2:$G$600,"")))} | C7: {=IF(COUNTIFS('Журнал'!$C$2:$C$600,$A7,'Журнал'!$B$2:$B$600,"Данил")=0,"",MAX(IF(('Журнал'!$C$2:$C$600=$A7)*('Журнал'!$B$2:$B$600="Данил")*('Журнал'!$A$2:$A$600=MAX(IF(('Журнал'!$C$2:$C$600=$A7)*('Журнал'!$B$2:$B$600="Данил"),'Журнал'!$A$2:$A$600,""))),'Журнал'!$G$2:$G$600,"")))} | D7: =IF(OR(B7="",B7=0),"",C7/B7-1) | E7: {=IF(COUNTIFS('Журнал'!$C$2:$C$600,$A7,'Журнал'!$B$2:$B$600,"Егор")=0,"",MAX(IF(('Журнал'!$C$2:$C$600=$A7)*('Журнал'!$B$2:$B$600="Егор")*('Журнал'!$A$2:$A$600=MIN(IF(('Журнал'!$C$2:$C$600=$A7)*('Журнал'!$B$2:$B$600="Егор"),'Журнал'!$A$2:$A$600,""))),'Журнал'!$G$2:$G$600,"")))} | F7: {=IF(COUNTIFS('Журнал'!$C$2:$C$600,$A7,'Журнал'!$B$2:$B$600,"Егор")=0,"",MAX(IF(('Журнал'!$C$2:$C$600=$A7)*('Журнал'!$B$2:$B$600="Егор")*('Журнал'!$A$2:$A$600=MAX(IF(('Журнал'!$C$2:$C$600=$A7)*('Журнал'!$B$2:$B$600="Егор"),'Журнал'!$A$2:$A$600,""))),'Журнал'!$G$2:$G$600,"")))} | G7: =IF(OR(E7="",E7=0),"",F7/E7-1)
A8: Румынская тяга | B8: {=IF(COUNTIFS('Журнал'!$C$2:$C$600,$A8,'Журнал'!$B$2:$B$600,"Данил")=0,"",MAX(IF(('Журнал'!$C$2:$C$600=$A8)*('Журнал'!$B$2:$B$600="Данил")*('Журнал'!$A$2:$A$600=MIN(IF(('Журнал'!$C$2:$C$600=$A8)*('Журнал'!$B$2:$B$600="Данил"),'Журнал'!$A$2:$A$600,""))),'Журнал'!$G$2:$G$600,"")))} -> 53.3 | C8: {=IF(COUNTIFS('Журнал'!$C$2:$C$600,$A8,'Журнал'!$B$2:$B$600,"Данил")=0,"",MAX(IF(('Журнал'!$C$2:$C$600=$A8)*('Журнал'!$B$2:$B$600="Данил")*('Журнал'!$A$2:$A$600=MAX(IF(('Журнал'!$C$2:$C$600=$A8)*('Журнал'!$B$2:$B$600="Данил"),'Журнал'!$A$2:$A$600,""))),'Журнал'!$G$2:$G$600,"")))} -> 53.3 | D8: =IF(OR(B8="",B8=0),"",C8/B8-1) -> 0 | E8: {=IF(COUNTIFS('Журнал'!$C$2:$C$600,$A8,'Журнал'!$B$2:$B$600,"Егор")=0,"",MAX(IF(('Журнал'!$C$2:$C$600=$A8)*('Журнал'!$B$2:$B$600="Егор")*('Журнал'!$A$2:$A$600=MIN(IF(('Журнал'!$C$2:$C$600=$A8)*('Журнал'!$B$2:$B$600="Егор"),'Журнал'!$A$2:$A$600,""))),'Журнал'!$G$2:$G$600,"")))} -> 80 | F8: {=IF(COUNTIFS('Журнал'!$C$2:$C$600,$A8,'Журнал'!$B$2:$B$600,"Егор")=0,"",MAX(IF(('Журнал'!$C$2:$C$600=$A8)*('Журнал'!$B$2:$B$600="Егор")*('Журнал'!$A$2:$A$600=MAX(IF(('Журнал'!$C$2:$C$600=$A8)*('Журнал'!$B$2:$B$600="Егор"),'Журнал'!$A$2:$A$600,""))),'Журнал'!$G$2:$G$600,"")))} -> 80 | G8: =IF(OR(E8="",E8=0),"",F8/E8-1) -> 0
A9: Жим гантелей на наклонной 30° | B9: {=IF(COUNTIFS('Журнал'!$C$2:$C$600,$A9,'Журнал'!$B$2:$B$600,"Данил")=0,"",MAX(IF(('Журнал'!$C$2:$C$600=$A9)*('Журнал'!$B$2:$B$600="Данил")*('Журнал'!$A$2:$A$600=MIN(IF(('Журнал'!$C$2:$C$600=$A9)*('Журнал'!$B$2:$B$600="Данил"),'Журнал'!$A$2:$A$600,""))),'Журнал'!$G$2:$G$600,"")))} -> 25.2 | C9: {=IF(COUNTIFS('Журнал'!$C$2:$C$600,$A9,'Журнал'!$B$2:$B$600,"Данил")=0,"",MAX(IF(('Журнал'!$C$2:$C$600=$A9)*('Журнал'!$B$2:$B$600="Данил")*('Журнал'!$A$2:$A$600=MAX(IF(('Журнал'!$C$2:$C$600=$A9)*('Журнал'!$B$2:$B$600="Данил"),'Журнал'!$A$2:$A$600,""))),'Журнал'!$G$2:$G$600,"")))} -> 25.2 | D9: =IF(OR(B9="",B9=0),"",C9/B9-1) -> 0 | E9: {=IF(COUNTIFS('Журнал'!$C$2:$C$600,$A9,'Журнал'!$B$2:$B$600,"Егор")=0,"",MAX(IF(('Журнал'!$C$2:$C$600=$A9)*('Журнал'!$B$2:$B$600="Егор")*('Журнал'!$A$2:$A$600=MIN(IF(('Журнал'!$C$2:$C$600=$A9)*('Журнал'!$B$2:$B$600="Егор"),'Журнал'!$A$2:$A$600,""))),'Журнал'!$G$2:$G$600,"")))} -> 33.6 | F9: {=IF(COUNTIFS('Журнал'!$C$2:$C$600,$A9,'Журнал'!$B$2:$B$600,"Егор")=0,"",MAX(IF(('Журнал'!$C$2:$C$600=$A9)*('Журнал'!$B$2:$B$600="Егор")*('Журнал'!$A$2:$A$600=MAX(IF(('Журнал'!$C$2:$C$600=$A9)*('Журнал'!$B$2:$B$600="Егор"),'Журнал'!$A$2:$A$600,""))),'Журнал'!$G$2:$G$600,"")))} -> 33.6 | G9: =IF(OR(E9="",E9=0),"",F9/E9-1) -> 0
A10: Тяга верхнего блока | B10: {=IF(COUNTIFS('Журнал'!$C$2:$C$600,$A10,'Журнал'!$B$2:$B$600,"Данил")=0,"",MAX(IF(('Журнал'!$C$2:$C$600=$A10)*('Журнал'!$B$2:$B$600="Данил")*('Журнал'!$A$2:$A$600=MIN(IF(('Журнал'!$C$2:$C$600=$A10)*('Журнал'!$B$2:$B$600="Данил"),'Журнал'!$A$2:$A$600,""))),'Журнал'!$G$2:$G$600,"")))} -> 112 | C10: {=IF(COUNTIFS('Журнал'!$C$2:$C$600,$A10,'Журнал'!$B$2:$B$600,"Данил")=0,"",MAX(IF(('Журнал'!$C$2:$C$600=$A10)*('Журнал'!$B$2:$B$600="Данил")*('Журнал'!$A$2:$A$600=MAX(IF(('Журнал'!$C$2:$C$600=$A10)*('Журнал'!$B$2:$B$600="Данил"),'Журнал'!$A$2:$A$600,""))),'Журнал'!$G$2:$G$600,"")))} -> 112 | D10: =IF(OR(B10="",B10=0),"",C10/B10-1) -> 0 | E10: {=IF(COUNTIFS('Журнал'!$C$2:$C$600,$A10,'Журнал'!$B$2:$B$600,"Егор")=0,"",MAX(IF(('Журнал'!$C$2:$C$600=$A10)*('Журнал'!$B$2:$B$600="Егор")*('Журнал'!$A$2:$A$600=MIN(IF(('Журнал'!$C$2:$C$600=$A10)*('Журнал'!$B$2:$B$600="Егор"),'Журнал'!$A$2:$A$600,""))),'Журнал'!$G$2:$G$600,"")))} -> 120 | F10: {=IF(COUNTIFS('Журнал'!$C$2:$C$600,$A10,'Журнал'!$B$2:$B$600,"Егор")=0,"",MAX(IF(('Журнал'!$C$2:$C$600=$A10)*('Журнал'!$B$2:$B$600="Егор")*('Журнал'!$A$2:$A$600=MAX(IF(('Журнал'!$C$2:$C$600=$A10)*('Журнал'!$B$2:$B$600="Егор"),'Журнал'!$A$2:$A$600,""))),'Журнал'!$G$2:$G$600,"")))} -> 120 | G10: =IF(OR(E10="",E10=0),"",F10/E10-1) -> 0
A11: Подъём штанги на бицепс | B11: {=IF(COUNTIFS('Журнал'!$C$2:$C$600,$A11,'Журнал'!$B$2:$B$600,"Данил")=0,"",MAX(IF(('Журнал'!$C$2:$C$600=$A11)*('Журнал'!$B$2:$B$600="Данил")*('Журнал'!$A$2:$A$600=MIN(IF(('Журнал'!$C$2:$C$600=$A11)*('Журнал'!$B$2:$B$600="Данил"),'Журнал'!$A$2:$A$600,""))),'Журнал'!$G$2:$G$600,"")))} -> 35 | C11: {=IF(COUNTIFS('Журнал'!$C$2:$C$600,$A11,'Журнал'!$B$2:$B$600,"Данил")=0,"",MAX(IF(('Журнал'!$C$2:$C$600=$A11)*('Журнал'!$B$2:$B$600="Данил")*('Журнал'!$A$2:$A$600=MAX(IF(('Журнал'!$C$2:$C$600=$A11)*('Журнал'!$B$2:$B$600="Данил"),'Журнал'!$A$2:$A$600,""))),'Журнал'!$G$2:$G$600,"")))} -> 35 | D11: =IF(OR(B11="",B11=0),"",C11/B11-1) -> 0 | E11: {=IF(COUNTIFS('Журнал'!$C$2:$C$600,$A11,'Журнал'!$B$2:$B$600,"Егор")=0,"",MAX(IF(('Журнал'!$C$2:$C$600=$A11)*('Журнал'!$B$2:$B$600="Егор")*('Журнал'!$A$2:$A$600=MIN(IF(('Журнал'!$C$2:$C$600=$A11)*('Журнал'!$B$2:$B$600="Егор"),'Журнал'!$A$2:$A$600,""))),'Журнал'!$G$2:$G$600,"")))} -> 56 | F11: {=IF(COUNTIFS('Журнал'!$C$2:$C$600,$A11,'Журнал'!$B$2:$B$600,"Егор")=0,"",MAX(IF(('Журнал'!$C$2:$C$600=$A11)*('Журнал'!$B$2:$B$600="Егор")*('Журнал'!$A$2:$A$600=MAX(IF(('Журнал'!$C$2:$C$600=$A11)*('Журнал'!$B$2:$B$600="Егор"),'Журнал'!$A$2:$A$600,""))),'Журнал'!$G$2:$G$600,"")))} -> 56 | G11: =IF(OR(E11="",E11=0),"",F11/E11-1) -> 0
A12: Французский жим | B12: {=IF(COUNTIFS('Журнал'!$C$2:$C$600,$A12,'Журнал'!$B$2:$B$600,"Данил")=0,"",MAX(IF(('Журнал'!$C$2:$C$600=$A12)*('Журнал'!$B$2:$B$600="Данил")*('Журнал'!$A$2:$A$600=MIN(IF(('Журнал'!$C$2:$C$600=$A12)*('Журнал'!$B$2:$B$600="Данил"),'Журнал'!$A$2:$A$600,""))),'Журнал'!$G$2:$G$600,"")))} -> 26.7 | C12: {=IF(COUNTIFS('Журнал'!$C$2:$C$600,$A12,'Журнал'!$B$2:$B$600,"Данил")=0,"",MAX(IF(('Журнал'!$C$2:$C$600=$A12)*('Журнал'!$B$2:$B$600="Данил")*('Журнал'!$A$2:$A$600=MAX(IF(('Журнал'!$C$2:$C$600=$A12)*('Журнал'!$B$2:$B$600="Данил"),'Журнал'!$A$2:$A$600,""))),'Журнал'!$G$2:$G$600,"")))} -> 26.7 | D12: =IF(OR(B12="",B12=0),"",C12/B12-1) -> 0 | E12: {=IF(COUNTIFS('Журнал'!$C$2:$C$600,$A12,'Журнал'!$B$2:$B$600,"Егор")=0,"",MAX(IF(('Журнал'!$C$2:$C$600=$A12)*('Журнал'!$B$2:$B$600="Егор")*('Журнал'!$A$2:$A$600=MIN(IF(('Журнал'!$C$2:$C$600=$A12)*('Журнал'!$B$2:$B$600="Егор"),'Журнал'!$A$2:$A$600,""))),'Журнал'!$G$2:$G$600,"")))} -> 35 | F12: {=IF(COUNTIFS('Журнал'!$C$2:$C$600,$A12,'Журнал'!$B$2:$B$600,"Егор")=0,"",MAX(IF(('Журнал'!$C$2:$C$600=$A12)*('Журнал'!$B$2:$B$600="Егор")*('Журнал'!$A$2:$A$600=MAX(IF(('Журнал'!$C$2:$C$600=$A12)*('Журнал'!$B$2:$B$600="Егор"),'Журнал'!$A$2:$A$600,""))),'Журнал'!$G$2:$G$600,"")))} -> 35 | G12: =IF(OR(E12="",E12=0),"",F12/E12-1) -> 0
A13: Гоблет-приседания | B13: {=IF(COUNTIFS('Журнал'!$C$2:$C$600,$A13,'Журнал'!$B$2:$B$600,"Данил")=0,"",MAX(IF(('Журнал'!$C$2:$C$600=$A13)*('Журнал'!$B$2:$B$600="Данил")*('Журнал'!$A$2:$A$600=MIN(IF(('Журнал'!$C$2:$C$600=$A13)*('Журнал'!$B$2:$B$600="Данил"),'Журнал'!$A$2:$A$600,""))),'Журнал'!$G$2:$G$600,"")))} -> 22.4 | C13: {=IF(COUNTIFS('Журнал'!$C$2:$C$600,$A13,'Журнал'!$B$2:$B$600,"Данил")=0,"",MAX(IF(('Журнал'!$C$2:$C$600=$A13)*('Журнал'!$B$2:$B$600="Данил")*('Журнал'!$A$2:$A$600=MAX(IF(('Журнал'!$C$2:$C$600=$A13)*('Журнал'!$B$2:$B$600="Данил"),'Журнал'!$A$2:$A$600,""))),'Журнал'!$G$2:$G$600,"")))} -> 22.4 | D13: =IF(OR(B13="",B13=0),"",C13/B13-1) -> 0 | E13: {=IF(COUNTIFS('Журнал'!$C$2:$C$600,$A13,'Журнал'!$B$2:$B$600,"Егор")=0,"",MAX(IF(('Журнал'!$C$2:$C$600=$A13)*('Журнал'!$B$2:$B$600="Егор")*('Журнал'!$A$2:$A$600=MIN(IF(('Журнал'!$C$2:$C$600=$A13)*('Журнал'!$B$2:$B$600="Егор"),'Журнал'!$A$2:$A$600,""))),'Журнал'!$G$2:$G$600,"")))} -> 33.6 | F13: {=IF(COUNTIFS('Журнал'!$C$2:$C$600,$A13,'Журнал'!$B$2:$B$600,"Егор")=0,"",MAX(IF(('Журнал'!$C$2:$C$600=$A13)*('Журнал'!$B$2:$B$600="Егор")*('Журнал'!$A$2:$A$600=MAX(IF(('Журнал'!$C$2:$C$600=$A13)*('Журнал'!$B$2:$B$600="Егор"),'Журнал'!$A$2:$A$600,""))),'Журнал'!$G$2:$G$600,"")))} -> 33.6 | G13: =IF(OR(E13="",E13=0),"",F13/E13-1) -> 0
A14: Разгибание ног сидя | B14: {=IF(COUNTIFS('Журнал'!$C$2:$C$600,$A14,'Журнал'!$B$2:$B$600,"Данил")=0,"",MAX(IF(('Журнал'!$C$2:$C$600=$A14)*('Журнал'!$B$2:$B$600="Данил")*('Журнал'!$A$2:$A$600=MIN(IF(('Журнал'!$C$2:$C$600=$A14)*('Журнал'!$B$2:$B$600="Данил"),'Журнал'!$A$2:$A$600,""))),'Журнал'!$G$2:$G$600,"")))} -> 70 | C14: {=IF(COUNTIFS('Журнал'!$C$2:$C$600,$A14,'Журнал'!$B$2:$B$600,"Данил")=0,"",MAX(IF(('Журнал'!$C$2:$C$600=$A14)*('Журнал'!$B$2:$B$600="Данил")*('Журнал'!$A$2:$A$600=MAX(IF(('Журнал'!$C$2:$C$600=$A14)*('Журнал'!$B$2:$B$600="Данил"),'Журнал'!$A$2:$A$600,""))),'Журнал'!$G$2:$G$600,"")))} -> 70 | D14: =IF(OR(B14="",B14=0),"",C14/B14-1) -> 0 | E14: {=IF(COUNTIFS('Журнал'!$C$2:$C$600,$A14,'Журнал'!$B$2:$B$600,"Егор")=0,"",MAX(IF(('Журнал'!$C$2:$C$600=$A14)*('Журнал'!$B$2:$B$600="Егор")*('Журнал'!$A$2:$A$600=MIN(IF(('Журнал'!$C$2:$C$600=$A14)*('Журнал'!$B$2:$B$600="Егор"),'Журнал'!$A$2:$A$600,""))),'Журнал'!$G$2:$G$600,"")))} -> 70 | F14: {=IF(COUNTIFS('Журнал'!$C$2:$C$600,$A14,'Журнал'!$B$2:$B$600,"Егор")=0,"",MAX(IF(('Журнал'!$C$2:$C$600=$A14)*('Журнал'!$B$2:$B$600="Егор")*('Журнал'!$A$2:$A$600=MAX(IF(('Журнал'!$C$2:$C$600=$A14)*('Журнал'!$B$2:$B$600="Егор"),'Журнал'!$A$2:$A$600,""))),'Журнал'!$G$2:$G$600,"")))} -> 70 | G14: =IF(OR(E14="",E14=0),"",F14/E14-1) -> 0
A15: Сгибание ног лёжа | B15: {=IF(COUNTIFS('Журнал'!$C$2:$C$600,$A15,'Журнал'!$B$2:$B$600,"Данил")=0,"",MAX(IF(('Журнал'!$C$2:$C$600=$A15)*('Журнал'!$B$2:$B$600="Данил")*('Журнал'!$A$2:$A$600=MIN(IF(('Журнал'!$C$2:$C$600=$A15)*('Журнал'!$B$2:$B$600="Данил"),'Журнал'!$A$2:$A$600,""))),'Журнал'!$G$2:$G$600,"")))} -> 35 | C15: {=IF(COUNTIFS('Журнал'!$C$2:$C$600,$A15,'Журнал'!$B$2:$B$600,"Данил")=0,"",MAX(IF(('Журнал'!$C$2:$C$600=$A15)*('Журнал'!$B$2:$B$600="Данил")*('Журнал'!$A$2:$A$600=MAX(IF(('Журнал'!$C$2:$C$600=$A15)*('Журнал'!$B$2:$B$600="Данил"),'Журнал'!$A$2:$A$600,""))),'Журнал'!$G$2:$G$600,"")))} -> 35 | D15: =IF(OR(B15="",B15=0),"",C15/B15-1) -> 0 | E15: {=IF(COUNTIFS('Журнал'!$C$2:$C$600,$A15,'Журнал'!$B$2:$B$600,"Егор")=0,"",MAX(IF(('Журнал'!$C$2:$C$600=$A15)*('Журнал'!$B$2:$B$600="Егор")*('Журнал'!$A$2:$A$600=MIN(IF(('Журнал'!$C$2:$C$600=$A15)*('Журнал'!$B$2:$B$600="Егор"),'Журнал'!$A$2:$A$600,""))),'Журнал'!$G$2:$G$600,"")))} -> 42 | F15: {=IF(COUNTIFS('Журнал'!$C$2:$C$600,$A15,'Журнал'!$B$2:$B$600,"Егор")=0,"",MAX(IF(('Журнал'!$C$2:$C$600=$A15)*('Журнал'!$B$2:$B$600="Егор")*('Журнал'!$A$2:$A$600=MAX(IF(('Журнал'!$C$2:$C$600=$A15)*('Журнал'!$B$2:$B$600="Егор"),'Журнал'!$A$2:$A$600,""))),'Журнал'!$G$2:$G$600,"")))} -> 42 | G15: =IF(OR(E15="",E15=0),"",F15/E15-1) -> 0

Sheet Графики
A1: Прогресс по e1RM (кг): Старт → Сейчас. Обновляется автоматически при заполнении «Журнала».

Sheet Динамика
A1: ДИНАМИКА e1RM ПО НЕДЕЛЯМ
A2: Упражнение → | B2: Жим гантелей на наклонной 30°
A3: Выбери упражнение в жёлтой ячейке. Точки на графике появляются сами по мере заполнения «Журнала». Пустые ячейки — в этот день упражнение не делали.
A4: Дата | B4: Данил e1RM | C4: Егор e1RM
A5: 46195 | B5: {=IF($A5="","",IF(COUNTIFS('Журнал'!$C$2:$C$600,$B$2,'Журнал'!$B$2:$B$600,"Данил",'Журнал'!$A$2:$A$600,$A5)=0,NA(),MAX(IF(('Журнал'!$C$2:$C$600=$B$2)*('Журнал'!$B$2:$B$600="Данил")*('Журнал'!$A$2:$A$600=$A5),'Журнал'!$G$2:$G$600,""))))} -> 25.2 | C5: {=IF($A5="","",IF(COUNTIFS('Журнал'!$C$2:$C$600,$B$2,'Журнал'!$B$2:$B$600,"Егор",'Журнал'!$A$2:$A$600,$A5)=0,NA(),MAX(IF(('Журнал'!$C$2:$C$600=$B$2)*('Журнал'!$B$2:$B$600="Егор")*('Журнал'!$A$2:$A$600=$A5),'Журнал'!$G$2:$G$600,""))))} -> 33.6
A6: 46196 | B6: {=IF($A6="","",IF(COUNTIFS('Журнал'!$C$2:$C$600,$B$2,'Журнал'!$B$2:$B$600,"Данил",'Журнал'!$A$2:$A$600,$A6)=0,NA(),MAX(IF(('Журнал'!$C$2:$C$600=$B$2)*('Журнал'!$B$2:$B$600="Данил")*('Журнал'!$A$2:$A$600=$A6),'Журнал'!$G$2:$G$600,""))))} -> #N/A | C6: {=IF($A6="","",IF(COUNTIFS('Журнал'!$C$2:$C$600,$B$2,'Журнал'!$B$2:$B$600,"Егор",'Журнал'!$A$2:$A$600,$A6)=0,NA(),MAX(IF(('Журнал'!$C$2:$C$600=$B$2)*('Журнал'!$B$2:$B$600="Егор")*('Журнал'!$A$2:$A$600=$A6),'Журнал'!$G$2:$G$600,""))))} -> #N/A
A7: 46198 | B7: {=IF($A7="","",IF(COUNTIFS('Журнал'!$C$2:$C$600,$B$2,'Журнал'!$B$2:$B$600,"Данил",'Журнал'!$A$2:$A$600,$A7)=0,NA(),MAX(IF(('Журнал'!$C$2:$C$600=$B$2)*('Журнал'!$B$2:$B$600="Данил")*('Журнал'!$A$2:$A$600=$A7),'Журнал'!$G$2:$G$600,""))))} -> #N/A | C7: {=IF($A7="","",IF(COUNTIFS('Журнал'!$C$2:$C$600,$B$2,'Журнал'!$B$2:$B$600,"Егор",'Журнал'!$A$2:$A$600,$A7)=0,NA(),MAX(IF(('Журнал'!$C$2:$C$600=$B$2)*('Журнал'!$B$2:$B$600="Егор")*('Журнал'!$A$2:$A$600=$A7),'Журнал'!$G$2:$G$600,""))))} -> #N/A
A8: 46199 | B8: {=IF($A8="","",IF(COUNTIFS('Журнал'!$C$2:$C$600,$B$2,'Журнал'!$B$2:$B$600,"Данил",'Журнал'!$A$2:$A$600,$A8)=0,NA(),MAX(IF(('Журнал'!$C$2:$C$600=$B$2)*('Журнал'!$B$2:$B$600="Данил")*('Журнал'!$A$2:$A$600=$A8),'Журнал'!$G$2:$G$600,""))))} -> #N/A | C8: {=IF($A8="","",IF(COUNTIFS('Журнал'!$C$2:$C$600,$B$2,'Журнал'!$B$2:$B$600,"Егор",'Журнал'!$A$2:$A$600,$A8)=0,NA(),MAX(IF(('Журнал'!$C$2:$C$600=$B$2)*('Журнал'!$B$2:$B$600="Егор")*('Журнал'!$A$2:$A$600=$A8),'Журнал'!$G$2:$G$600,""))))} -> #N/A
A9: 46202 | B9: {=IF($A9="","",IF(COUNTIFS('Журнал'!$C$2:$C$600,$B$2,'Журнал'!$B$2:$B$600,"Данил",'Журнал'!$A$2:$A$600,$A9)=0,NA(),MAX(IF(('Журнал'!$C$2:$C$600=$B$2)*('Журнал'!$B$2:$B$600="Данил")*('Журнал'!$A$2:$A$600=$A9),'Журнал'!$G$2:$G$600,""))))} -> #N/A | C9: {=IF($A9="","",IF(COUNTIFS('Журнал'!$C$2:$C$600,$B$2,'Журнал'!$B$2:$B$600,"Егор",'Журнал'!$A$2:$A$600,$A9)=0,NA(),MAX(IF(('Журнал'!$C$2:$C$600=$B$2)*('Журнал'!$B$2:$B$600="Егор")*('Журнал'!$A$2:$A$600=$A9),'Журнал'!$G$2:$G$600,""))))} -> #N/A
A10: 46203 | B10: {=IF($A10="","",IF(COUNTIFS('Журнал'!$C$2:$C$600,$B$2,'Журнал'!$B$2:$B$600,"Данил",'Журнал'!$A$2:$A$600,$A10)=0,NA(),MAX(IF(('Журнал'!$C$2:$C$600=$B$2)*('Журнал'!$B$2:$B$600="Данил")*('Журнал'!$A$2:$A$600=$A10),'Журнал'!$G$2:$G$600,""))))} -> #N/A | C10: {=IF($A10="","",IF(COUNTIFS('Журнал'!$C$2:$C$600,$B$2,'Журнал'!$B$2:$B$600,"Егор",'Журнал'!$A$2:$A$600,$A10)=0,NA(),MAX(IF(('Журнал'!$C$2:$C$600=$B$2)*('Журнал'!$B$2:$B$600="Егор")*('Журнал'!$A$2:$A$600=$A10),'Журнал'!$G$2:$G$600,""))))} -> #N/A
A11: 46205 | B11: {=IF($A11="","",IF(COUNTIFS('Журнал'!$C$2:$C$600,$B$2,'Журнал'!$B$2:$B$600,"Данил",'Журнал'!$A$2:$A$600,$A11)=0,NA(),MAX(IF(('Журнал'!$C$2:$C$600=$B$2)*('Журнал'!$B$2:$B$600="Данил")*('Журнал'!$A$2:$A$600=$A11),'Журнал'!$G$2:$G$600,""))))} -> #N/A | C11: {=IF($A11="","",IF(COUNTIFS('Журнал'!$C$2:$C$600,$B$2,'Журнал'!$B$2:$B$600,"Егор",'Журнал'!$A$2:$A$600,$A11)=0,NA(),MAX(IF(('Журнал'!$C$2:$C$600=$B$2)*('Журнал'!$B$2:$B$600="Егор")*('Журнал'!$A$2:$A$600=$A11),'Журнал'!$G$2:$G$600,""))))} -> #N/A
A12: 46206 | B12: {=IF($A12="","",IF(COUNTIFS('Журнал'!$C$2:$C$600,$B$2,'Журнал'!$B$2:$B$600,"Данил",'Журнал'!$A$2:$A$600,$A12)=0,NA(),MAX(IF(('Журнал'!$C$2:$C$600=$B$2)*('Журнал'!$B$2:$B$600="Данил")*('Журнал'!$A$2:$A$600=$A12),'Журнал'!$G$2:$G$600,""))))} -> #N/A | C12: {=IF($A12="","",IF(COUNTIFS('Журнал'!$C$2:$C$600,$B$2,'Журнал'!$B$2:$B$600,"Егор",'Журнал'!$A$2:$A$600,$A12)=0,NA(),MAX(IF(('Журнал'!$C$2:$C$600=$B$2)*('Журнал'!$B$2:$B$600="Егор")*('Журнал'!$A$2:$A$600=$A12),'Журнал'!$G$2:$G$600,""))))} -> #N/A
A13: 46209 | B13: {=IF($A13="","",IF(COUNTIFS('Журнал'!$C$2:$C$600,$B$2,'Журнал'!$B$2:$B$600,"Данил",'Журнал'!$A$2:$A$600,$A13)=0,NA(),MAX(IF(('Журнал'!$C$2:$C$600=$B$2)*('Журнал'!$B$2:$B$600="Данил")*('Журнал'!$A$2:$A$600=$A13),'Журнал'!$G$2:$G$600,""))))} -> #N/A | C13: {=IF($A13="","",IF(COUNTIFS('Журнал'!$C$2:$C$600,$B$2,'Журнал'!$B$2:$B$600,"Егор",'Журнал'!$A$2:$A$600,$A13)=0,NA(),MAX(IF(('Журнал'!$C$2:$C$600=$B$2)*('Журнал'!$B$2:$B$600="Егор")*('Журнал'!$A$2:$A$600=$A13),'Журнал'!$G$2:$G$600,""))))} -> #N/A
A14: 46210 | B14: {=IF($A14="","",IF(COUNTIFS('Журнал'!$C$2:$C$600,$B$2,'Журнал'!$B$2:$B$600,"Данил",'Журнал'!$A$2:$A$600,$A14)=0,NA(),MAX(IF(('Журнал'!$C$2:$C$600=$B$2)*('Журнал'!$B$2:$B$600="Данил")*('Журнал'!$A$2:$A$600=$A14),'Журнал'!$G$2:$G$600,""))))} -> #N/A | C14: {=IF($A14="","",IF(COUNTIFS('Журнал'!$C$2:$C$600,$B$2,'Журнал'!$B$2:$B$600,"Егор",'Журнал'!$A$2:$A$600,$A14)=0,NA(),MAX(IF(('Журнал'!$C$2:$C$600=$B$2)*('Журнал'!$B$2:$B$600="Егор")*('Журнал'!$A$2:$A$600=$A14),'Журнал'!$G$2:$G$600,""))))} -> #N/A
A15: 46212 | B15: {=IF($A15="","",IF(COUNTIFS('Журнал'!$C$2:$C$600,$B$2,'Журнал'!$B$2:$B$600,"Данил",'Журнал'!$A$2:$A$600,$A15)=0,NA(),MAX(IF(('Журнал'!$C$2:$C$600=$B$2)*('Журнал'!$B$2:$B$600="Данил")*('Журнал'!$A$2:$A$600=$A15),'Журнал'!$G$2:$G$600,""))))} -> #N/A | C15: {=IF($A15="","",IF(COUNTIFS('Журнал'!$C$2:$C$600,$B$2,'Журнал'!$B$2:$B$600,"Егор",'Журнал'!$A$2:$A$600,$A15)=0,NA(),MAX(IF(('Журнал'!$C$2:$C$600=$B$2)*('Журнал'!$B$2:$B$600="Егор")*('Журнал'!$A$2:$A$600=$A15),'Журнал'!$G$2:$G$600,""))))} -> #N/A
A16: 46213 | B16: {=IF($A16="","",IF(COUNTIFS('Журнал'!$C$2:$C$600,$B$2,'Журнал'!$B$2:$B$600,"Данил",'Журнал'!$A$2:$A$600,$A16)=0,NA(),MAX(IF(('Журнал'!$C$2:$C$600=$B$2)*('Журнал'!$B$2:$B$600="Данил")*('Журнал'!$A$2:$A$600=$A16),'Журнал'!$G$2:$G$600,""))))} -> #N/A | C16: {=IF($A16="","",IF(COUNTIFS('Журнал'!$C$2:$C$600,$B$2,'Журнал'!$B$2:$B$600,"Егор",'Журнал'!$A$2:$A$600,$A16)=0,NA(),MAX(IF(('Журнал'!$C$2:$C$600=$B$2)*('Журнал'!$B$2:$B$600="Егор")*('Журнал'!$A$2:$A$600=$A16),'Журнал'!$G$2:$G$600,""))))} -> #N/A
... A52: 46276 | B52: {=IF($A52="","",IF(COUNTIFS('Журнал'!$C$2:$C$600,$B$2,'Журнал'!$B$2:$B$600,"Данил",'Журнал'!$A$2:$A$600,$A52)=0,NA(),MAX(IF(('Журнал'!$C$2:$C$600=$B$2)*('Журнал'!$B$2:$B$600="Данил")*('Журнал'!$A$2:$A$600=$A52),'Журнал'!$G$2:$G$600,""))))} -> #N/A | C52: {=IF($A52="","",IF(COUNTIFS('Журнал'!$C$2:$C$600,$B$2,'Журнал'!$B$2:$B$600,"Егор",'Журнал'!$A$2:$A$600,$A52)=0,NA(),MAX(IF(('Журнал'!$C$2:$C$600=$B$2)*('Журнал'!$B$2:$B$600="Егор")*('Журнал'!$A$2:$A$600=$A52),'Журнал'!$G$2:$G$600,""))))} -> #N/A

Sheet Замены
A1: Базовое движение | B1: Чем заменить через 5–6 недель (тот же паттерн)
A2: Жим штанги лёжа (на максимум) | B2: Жим в Смите · жим узким хватом · жим гантелей лёжа (когда нужна разгрузка плеча)
A3: Тяга штанги в наклоне | B3: Тяга Т-грифа · тяга гантели одной рукой · тяга в наклоне обратным хватом
A4: Тяга верхнего блока | B4: Подтягивания · тяга блока узким хватом · пуловер на блоке
A5: Жим гантелей сидя (плечи) | B5: Landmine-жим · Арнольд-жим (легко) · жим стоя в Смите перед собой
A6: Приседания со штангой | B6: Фронтальные приседания · гоблет-приседания · выпады с гантелями
A7: Румынская тяга | B7: Гиперэкстензия с весом · сгибание ног стоя · ягодичный мост
A8: Махи в стороны | B8: Махи в кроссовере · отведение в тренажёре · махи с паузой вверху
A9: Face pull / задняя дельта | B9: Разведение в кроссовере · обратная бабочка · тяга каната на заднюю дельту

Sheet Справочники
A1: Упражнения | C1: Кто
A2: Жим штанги лёжа | C2: Данил
A3: Жим гантелей на наклонной 30° | C3: Егор
A4: Жим гантелей лёжа (гориз.)
A5: Тяга штанги в наклоне
A6: Тяга верхнего блока
A7: Махи гантелями в стороны
A8: Французский жим
A9: Подъём штанги на бицепс
A10: Внешняя ротация плеча
A11: Приседания со штангой
A12: Гоблет-приседания
A13: Румынская тяга
A14: Разгибание ног сидя
A15: Сгибание ног лёжа
... A27: Планка
